[2018-12-12 13:54:57 +0800] [30535] [INFO] Starting gunicorn 19.9.0
[2018-12-12 13:54:57 +0800] [30535] [INFO] Listening at: http://0.0.0.0:6789 (30535)
[2018-12-12 13:54:57 +0800] [30535] [INFO] Using worker: gevent
[2018-12-12 13:54:57 +0800] [30538] [INFO] Booting worker with pid: 30538
[2018-12-12 13:54:57 +0800] [30539] [INFO] Booting worker with pid: 30539
[2018-12-12 13:54:57 +0800] [30540] [INFO] Booting worker with pid: 30540
[2018-12-12 13:54:57 +0800] [30538] [ERROR] Exception in worker process
Traceback (most recent call last):
  File "/Users/apple/anaconda3/lib/python3.7/site-packages/gunicorn/arbiter.py", line 583, in spawn_worker
    worker.init_process()
  File "/Users/apple/anaconda3/lib/python3.7/site-packages/gunicorn/workers/ggevent.py", line 203, in init_process
    super(GeventWorker, self).init_process()
  File "/Users/apple/anaconda3/lib/python3.7/site-packages/gunicorn/workers/base.py", line 129, in init_process
    self.load_wsgi()
  File "/Users/apple/anaconda3/lib/python3.7/site-packages/gunicorn/workers/base.py", line 138, in load_wsgi
    self.wsgi = self.app.wsgi()
  File "/Users/apple/anaconda3/lib/python3.7/site-packages/gunicorn/app/base.py", line 67, in wsgi
    self.callable = self.load()
  File "/Users/apple/anaconda3/lib/python3.7/site-packages/gunicorn/app/wsgiapp.py", line 52, in load
    return self.load_wsgiapp()
  File "/Users/apple/anaconda3/lib/python3.7/site-packages/gunicorn/app/wsgiapp.py", line 41, in load_wsgiapp
    return util.import_app(self.app_uri)
  File "/Users/apple/anaconda3/lib/python3.7/site-packages/gunicorn/util.py", line 350, in import_app
    __import__(module)
ModuleNotFoundError: No module named 'master'
[2018-12-12 13:54:57 +0800] [30538] [INFO] Worker exiting (pid: 30538)
[2018-12-12 13:54:57 +0800] [30539] [ERROR] Exception in worker process
Traceback (most recent call last):
  File "/Users/apple/anaconda3/lib/python3.7/site-packages/gunicorn/arbiter.py", line 583, in spawn_worker
    worker.init_process()
  File "/Users/apple/anaconda3/lib/python3.7/site-packages/gunicorn/workers/ggevent.py", line 203, in init_process
    super(GeventWorker, self).init_process()
  File "/Users/apple/anaconda3/lib/python3.7/site-packages/gunicorn/workers/base.py", line 129, in init_process
    self.load_wsgi()
  File "/Users/apple/anaconda3/lib/python3.7/site-packages/gunicorn/workers/base.py", line 138, in load_wsgi
    self.wsgi = self.app.wsgi()
  File "/Users/apple/anaconda3/lib/python3.7/site-packages/gunicorn/app/base.py", line 67, in wsgi
    self.callable = self.load()
  File "/Users/apple/anaconda3/lib/python3.7/site-packages/gunicorn/app/wsgiapp.py", line 52, in load
    return self.load_wsgiapp()
  File "/Users/apple/anaconda3/lib/python3.7/site-packages/gunicorn/app/wsgiapp.py", line 41, in load_wsgiapp
    return util.import_app(self.app_uri)
  File "/Users/apple/anaconda3/lib/python3.7/site-packages/gunicorn/util.py", line 350, in import_app
    __import__(module)
ModuleNotFoundError: No module named 'master'
[2018-12-12 13:54:57 +0800] [30539] [INFO] Worker exiting (pid: 30539)
[2018-12-12 13:54:57 +0800] [30540] [ERROR] Exception in worker process
Traceback (most recent call last):
  File "/Users/apple/anaconda3/lib/python3.7/site-packages/gunicorn/arbiter.py", line 583, in spawn_worker
    worker.init_process()
  File "/Users/apple/anaconda3/lib/python3.7/site-packages/gunicorn/workers/ggevent.py", line 203, in init_process
    super(GeventWorker, self).init_process()
  File "/Users/apple/anaconda3/lib/python3.7/site-packages/gunicorn/workers/base.py", line 129, in init_process
    self.load_wsgi()
  File "/Users/apple/anaconda3/lib/python3.7/site-packages/gunicorn/workers/base.py", line 138, in load_wsgi
    self.wsgi = self.app.wsgi()
  File "/Users/apple/anaconda3/lib/python3.7/site-packages/gunicorn/app/base.py", line 67, in wsgi
    self.callable = self.load()
  File "/Users/apple/anaconda3/lib/python3.7/site-packages/gunicorn/app/wsgiapp.py", line 52, in load
    return self.load_wsgiapp()
  File "/Users/apple/anaconda3/lib/python3.7/site-packages/gunicorn/app/wsgiapp.py", line 41, in load_wsgiapp
    return util.import_app(self.app_uri)
  File "/Users/apple/anaconda3/lib/python3.7/site-packages/gunicorn/util.py", line 350, in import_app
    __import__(module)
ModuleNotFoundError: No module named 'master'
[2018-12-12 13:54:57 +0800] [30540] [INFO] Worker exiting (pid: 30540)
[2018-12-12 13:54:57 +0800] [30541] [INFO] Booting worker with pid: 30541
[2018-12-12 13:54:57 +0800] [30541] [ERROR] Exception in worker process
Traceback (most recent call last):
  File "/Users/apple/anaconda3/lib/python3.7/site-packages/gunicorn/arbiter.py", line 583, in spawn_worker
    worker.init_process()
  File "/Users/apple/anaconda3/lib/python3.7/site-packages/gunicorn/workers/ggevent.py", line 203, in init_process
    super(GeventWorker, self).init_process()
  File "/Users/apple/anaconda3/lib/python3.7/site-packages/gunicorn/workers/base.py", line 129, in init_process
    self.load_wsgi()
  File "/Users/apple/anaconda3/lib/python3.7/site-packages/gunicorn/workers/base.py", line 138, in load_wsgi
    self.wsgi = self.app.wsgi()
  File "/Users/apple/anaconda3/lib/python3.7/site-packages/gunicorn/app/base.py", line 67, in wsgi
    self.callable = self.load()
  File "/Users/apple/anaconda3/lib/python3.7/site-packages/gunicorn/app/wsgiapp.py", line 52, in load
    return self.load_wsgiapp()
  File "/Users/apple/anaconda3/lib/python3.7/site-packages/gunicorn/app/wsgiapp.py", line 41, in load_wsgiapp
    return util.import_app(self.app_uri)
  File "/Users/apple/anaconda3/lib/python3.7/site-packages/gunicorn/util.py", line 350, in import_app
    __import__(module)
ModuleNotFoundError: No module named 'master'
[2018-12-12 13:54:57 +0800] [30541] [INFO] Worker exiting (pid: 30541)
Traceback (most recent call last):
  File "/Users/apple/anaconda3/lib/python3.7/site-packages/gunicorn/arbiter.py", line 203, in run
    self.manage_workers()
  File "/Users/apple/anaconda3/lib/python3.7/site-packages/gunicorn/arbiter.py", line 545, in manage_workers
    self.spawn_workers()
  File "/Users/apple/anaconda3/lib/python3.7/site-packages/gunicorn/arbiter.py", line 617, in spawn_workers
    time.sleep(0.1 * random.random())
  File "/Users/apple/anaconda3/lib/python3.7/site-packages/gunicorn/arbiter.py", line 245, in handle_chld
    self.reap_workers()
  File "/Users/apple/anaconda3/lib/python3.7/site-packages/gunicorn/arbiter.py", line 525, in reap_workers
    raise HaltServer(reason, self.WORKER_BOOT_ERROR)
gunicorn.errors.HaltServer: <HaltServer 'Worker failed to boot.' 3>

During handling of the above exception, another exception occurred:

Traceback (most recent call last):
  File "/Users/apple/anaconda3/bin/gunicorn", line 11, in <module>
    sys.exit(run())
  File "/Users/apple/anaconda3/lib/python3.7/site-packages/gunicorn/app/wsgiapp.py", line 61, in run
    WSGIApplication("%(prog)s [OPTIONS] [APP_MODULE]").run()
  File "/Users/apple/anaconda3/lib/python3.7/site-packages/gunicorn/app/base.py", line 223, in run
    super(Application, self).run()
  File "/Users/apple/anaconda3/lib/python3.7/site-packages/gunicorn/app/base.py", line 72, in run
    Arbiter(self).run()
  File "/Users/apple/anaconda3/lib/python3.7/site-packages/gunicorn/arbiter.py", line 232, in run
    self.halt(reason=inst.reason, exit_status=inst.exit_status)
  File "/Users/apple/anaconda3/lib/python3.7/site-packages/gunicorn/arbiter.py", line 345, in halt
    self.stop()
  File "/Users/apple/anaconda3/lib/python3.7/site-packages/gunicorn/arbiter.py", line 393, in stop
    time.sleep(0.1)
  File "/Users/apple/anaconda3/lib/python3.7/site-packages/gunicorn/arbiter.py", line 245, in handle_chld
    self.reap_workers()
  File "/Users/apple/anaconda3/lib/python3.7/site-packages/gunicorn/arbiter.py", line 525, in reap_workers
    raise HaltServer(reason, self.WORKER_BOOT_ERROR)
gunicorn.errors.HaltServer: <HaltServer 'Worker failed to boot.' 3>
[2018-12-12 13:55:56 +0800] [30577] [INFO] Starting gunicorn 19.9.0
[2018-12-12 13:55:56 +0800] [30577] [INFO] Listening at: http://0.0.0.0:6789 (30577)
[2018-12-12 13:55:56 +0800] [30577] [INFO] Using worker: gevent
[2018-12-12 13:55:56 +0800] [30580] [INFO] Booting worker with pid: 30580
[2018-12-12 13:55:56 +0800] [30581] [INFO] Booting worker with pid: 30581
[2018-12-12 13:55:56 +0800] [30582] [INFO] Booting worker with pid: 30582
[2018-12-12 13:55:56 +0800] [30583] [INFO] Booting worker with pid: 30583
[2018-12-12 13:55:56 +0800] [30581] [ERROR] Exception in worker process
Traceback (most recent call last):
  File "/Users/apple/anaconda3/lib/python3.7/site-packages/gunicorn/arbiter.py", line 583, in spawn_worker
    worker.init_process()
  File "/Users/apple/anaconda3/lib/python3.7/site-packages/gunicorn/workers/ggevent.py", line 203, in init_process
    super(GeventWorker, self).init_process()
  File "/Users/apple/anaconda3/lib/python3.7/site-packages/gunicorn/workers/base.py", line 129, in init_process
    self.load_wsgi()
  File "/Users/apple/anaconda3/lib/python3.7/site-packages/gunicorn/workers/base.py", line 138, in load_wsgi
    self.wsgi = self.app.wsgi()
  File "/Users/apple/anaconda3/lib/python3.7/site-packages/gunicorn/app/base.py", line 67, in wsgi
    self.callable = self.load()
  File "/Users/apple/anaconda3/lib/python3.7/site-packages/gunicorn/app/wsgiapp.py", line 52, in load
    return self.load_wsgiapp()
  File "/Users/apple/anaconda3/lib/python3.7/site-packages/gunicorn/app/wsgiapp.py", line 41, in load_wsgiapp
    return util.import_app(self.app_uri)
  File "/Users/apple/anaconda3/lib/python3.7/site-packages/gunicorn/util.py", line 350, in import_app
    __import__(module)
ModuleNotFoundError: No module named 'master'
[2018-12-12 13:55:56 +0800] [30581] [INFO] Worker exiting (pid: 30581)
[2018-12-12 13:55:56 +0800] [30580] [ERROR] Exception in worker process
Traceback (most recent call last):
  File "/Users/apple/anaconda3/lib/python3.7/site-packages/gunicorn/arbiter.py", line 583, in spawn_worker
    worker.init_process()
  File "/Users/apple/anaconda3/lib/python3.7/site-packages/gunicorn/workers/ggevent.py", line 203, in init_process
    super(GeventWorker, self).init_process()
  File "/Users/apple/anaconda3/lib/python3.7/site-packages/gunicorn/workers/base.py", line 129, in init_process
    self.load_wsgi()
  File "/Users/apple/anaconda3/lib/python3.7/site-packages/gunicorn/workers/base.py", line 138, in load_wsgi
    self.wsgi = self.app.wsgi()
  File "/Users/apple/anaconda3/lib/python3.7/site-packages/gunicorn/app/base.py", line 67, in wsgi
    self.callable = self.load()
  File "/Users/apple/anaconda3/lib/python3.7/site-packages/gunicorn/app/wsgiapp.py", line 52, in load
    return self.load_wsgiapp()
  File "/Users/apple/anaconda3/lib/python3.7/site-packages/gunicorn/app/wsgiapp.py", line 41, in load_wsgiapp
    return util.import_app(self.app_uri)
  File "/Users/apple/anaconda3/lib/python3.7/site-packages/gunicorn/util.py", line 350, in import_app
    __import__(module)
ModuleNotFoundError: No module named 'master'
[2018-12-12 13:55:56 +0800] [30580] [INFO] Worker exiting (pid: 30580)
[2018-12-12 13:55:57 +0800] [30582] [ERROR] Exception in worker process
Traceback (most recent call last):
  File "/Users/apple/anaconda3/lib/python3.7/site-packages/gunicorn/arbiter.py", line 583, in spawn_worker
    worker.init_process()
  File "/Users/apple/anaconda3/lib/python3.7/site-packages/gunicorn/workers/ggevent.py", line 203, in init_process
    super(GeventWorker, self).init_process()
  File "/Users/apple/anaconda3/lib/python3.7/site-packages/gunicorn/workers/base.py", line 129, in init_process
    self.load_wsgi()
  File "/Users/apple/anaconda3/lib/python3.7/site-packages/gunicorn/workers/base.py", line 138, in load_wsgi
    self.wsgi = self.app.wsgi()
  File "/Users/apple/anaconda3/lib/python3.7/site-packages/gunicorn/app/base.py", line 67, in wsgi
    self.callable = self.load()
  File "/Users/apple/anaconda3/lib/python3.7/site-packages/gunicorn/app/wsgiapp.py", line 52, in load
    return self.load_wsgiapp()
  File "/Users/apple/anaconda3/lib/python3.7/site-packages/gunicorn/app/wsgiapp.py", line 41, in load_wsgiapp
    return util.import_app(self.app_uri)
  File "/Users/apple/anaconda3/lib/python3.7/site-packages/gunicorn/util.py", line 350, in import_app
    __import__(module)
ModuleNotFoundError: No module named 'master'
[2018-12-12 13:55:57 +0800] [30582] [INFO] Worker exiting (pid: 30582)
[2018-12-12 13:55:57 +0800] [30583] [ERROR] Exception in worker process
Traceback (most recent call last):
  File "/Users/apple/anaconda3/lib/python3.7/site-packages/gunicorn/arbiter.py", line 583, in spawn_worker
    worker.init_process()
  File "/Users/apple/anaconda3/lib/python3.7/site-packages/gunicorn/workers/ggevent.py", line 203, in init_process
    super(GeventWorker, self).init_process()
  File "/Users/apple/anaconda3/lib/python3.7/site-packages/gunicorn/workers/base.py", line 129, in init_process
    self.load_wsgi()
  File "/Users/apple/anaconda3/lib/python3.7/site-packages/gunicorn/workers/base.py", line 138, in load_wsgi
    self.wsgi = self.app.wsgi()
  File "/Users/apple/anaconda3/lib/python3.7/site-packages/gunicorn/app/base.py", line 67, in wsgi
    self.callable = self.load()
  File "/Users/apple/anaconda3/lib/python3.7/site-packages/gunicorn/app/wsgiapp.py", line 52, in load
    return self.load_wsgiapp()
  File "/Users/apple/anaconda3/lib/python3.7/site-packages/gunicorn/app/wsgiapp.py", line 41, in load_wsgiapp
    return util.import_app(self.app_uri)
  File "/Users/apple/anaconda3/lib/python3.7/site-packages/gunicorn/util.py", line 350, in import_app
    __import__(module)
ModuleNotFoundError: No module named 'master'
[2018-12-12 13:55:57 +0800] [30583] [INFO] Worker exiting (pid: 30583)
[2018-12-12 13:55:57 +0800] [30577] [INFO] Shutting down: Master
[2018-12-12 13:55:57 +0800] [30577] [INFO] Reason: Worker failed to boot.
[2018-12-12 13:56:35 +0800] [30588] [INFO] Starting gunicorn 19.9.0
[2018-12-12 13:56:35 +0800] [30588] [INFO] Listening at: http://0.0.0.0:6789 (30588)
[2018-12-12 13:56:35 +0800] [30588] [INFO] Using worker: gevent
[2018-12-12 13:56:35 +0800] [30591] [INFO] Booting worker with pid: 30591
[2018-12-12 13:56:35 +0800] [30592] [INFO] Booting worker with pid: 30592
[2018-12-12 13:56:36 +0800] [30593] [INFO] Booting worker with pid: 30593
[2018-12-12 13:56:36 +0800] [30594] [INFO] Booting worker with pid: 30594
[2018-12-12 13:56:44 +0800] [30588] [INFO] Handling signal: int
[2018-12-12 13:56:44 +0800] [30594] [INFO] Worker exiting (pid: 30594)
[2018-12-12 13:56:44 +0800] [30593] [INFO] Worker exiting (pid: 30593)
[2018-12-12 13:56:44 +0800] [30592] [INFO] Worker exiting (pid: 30592)
[2018-12-12 13:56:44 +0800] [30591] [INFO] Worker exiting (pid: 30591)
[2018-12-12 13:56:45 +0800] [30588] [INFO] Shutting down: Master
[2018-12-12 14:01:19 +0800] [30735] [INFO] Starting gunicorn 19.9.0
[2018-12-12 14:01:19 +0800] [30735] [INFO] Listening at: http://0.0.0.0:6789 (30735)
[2018-12-12 14:01:19 +0800] [30735] [INFO] Using worker: gevent
[2018-12-12 14:01:19 +0800] [30743] [INFO] Booting worker with pid: 30743
[2018-12-12 14:01:19 +0800] [30744] [INFO] Booting worker with pid: 30744
[2018-12-12 14:01:19 +0800] [30745] [INFO] Booting worker with pid: 30745
[2018-12-12 14:01:19 +0800] [30746] [INFO] Booting worker with pid: 30746
[2018-12-12 14:15:54 +0800] [30965] [INFO] Starting gunicorn 19.9.0
[2018-12-12 14:15:54 +0800] [30965] [INFO] Listening at: http://0.0.0.0:6789 (30965)
[2018-12-12 14:15:54 +0800] [30965] [INFO] Using worker: gevent
[2018-12-12 14:15:54 +0800] [30974] [INFO] Booting worker with pid: 30974
[2018-12-12 14:15:54 +0800] [30975] [INFO] Booting worker with pid: 30975
[2018-12-12 14:15:55 +0800] [30976] [INFO] Booting worker with pid: 30976
[2018-12-12 14:15:55 +0800] [30977] [INFO] Booting worker with pid: 30977
[2018-12-12 14:15:55 +0800] [30975] [ERROR] Exception in worker process
Traceback (most recent call last):
  File "/Users/apple/anaconda3/lib/python3.7/site-packages/gunicorn/arbiter.py", line 583, in spawn_worker
    worker.init_process()
  File "/Users/apple/anaconda3/lib/python3.7/site-packages/gunicorn/workers/ggevent.py", line 203, in init_process
    super(GeventWorker, self).init_process()
  File "/Users/apple/anaconda3/lib/python3.7/site-packages/gunicorn/workers/base.py", line 129, in init_process
    self.load_wsgi()
  File "/Users/apple/anaconda3/lib/python3.7/site-packages/gunicorn/workers/base.py", line 138, in load_wsgi
    self.wsgi = self.app.wsgi()
  File "/Users/apple/anaconda3/lib/python3.7/site-packages/gunicorn/app/base.py", line 67, in wsgi
    self.callable = self.load()
  File "/Users/apple/anaconda3/lib/python3.7/site-packages/gunicorn/app/wsgiapp.py", line 52, in load
    return self.load_wsgiapp()
  File "/Users/apple/anaconda3/lib/python3.7/site-packages/gunicorn/app/wsgiapp.py", line 41, in load_wsgiapp
    return util.import_app(self.app_uri)
  File "/Users/apple/anaconda3/lib/python3.7/site-packages/gunicorn/util.py", line 350, in import_app
    __import__(module)
  File "/Users/apple/Desktop/query_mobile/app.py", line 5, in <module>
    from query import query_all
ImportError: cannot import name 'query_all' from 'query' (unknown location)
[2018-12-12 14:15:55 +0800] [30974] [ERROR] Exception in worker process
Traceback (most recent call last):
  File "/Users/apple/anaconda3/lib/python3.7/site-packages/gunicorn/arbiter.py", line 583, in spawn_worker
    worker.init_process()
  File "/Users/apple/anaconda3/lib/python3.7/site-packages/gunicorn/workers/ggevent.py", line 203, in init_process
    super(GeventWorker, self).init_process()
  File "/Users/apple/anaconda3/lib/python3.7/site-packages/gunicorn/workers/base.py", line 129, in init_process
    self.load_wsgi()
  File "/Users/apple/anaconda3/lib/python3.7/site-packages/gunicorn/workers/base.py", line 138, in load_wsgi
    self.wsgi = self.app.wsgi()
  File "/Users/apple/anaconda3/lib/python3.7/site-packages/gunicorn/app/base.py", line 67, in wsgi
    self.callable = self.load()
  File "/Users/apple/anaconda3/lib/python3.7/site-packages/gunicorn/app/wsgiapp.py", line 52, in load
    return self.load_wsgiapp()
  File "/Users/apple/anaconda3/lib/python3.7/site-packages/gunicorn/app/wsgiapp.py", line 41, in load_wsgiapp
    return util.import_app(self.app_uri)
  File "/Users/apple/anaconda3/lib/python3.7/site-packages/gunicorn/util.py", line 350, in import_app
    __import__(module)
  File "/Users/apple/Desktop/query_mobile/app.py", line 5, in <module>
    from query import query_all
ImportError: cannot import name 'query_all' from 'query' (unknown location)
[2018-12-12 14:15:55 +0800] [30974] [INFO] Worker exiting (pid: 30974)
[2018-12-12 14:15:55 +0800] [30975] [INFO] Worker exiting (pid: 30975)
[2018-12-12 14:15:55 +0800] [30976] [ERROR] Exception in worker process
Traceback (most recent call last):
  File "/Users/apple/anaconda3/lib/python3.7/site-packages/gunicorn/arbiter.py", line 583, in spawn_worker
    worker.init_process()
  File "/Users/apple/anaconda3/lib/python3.7/site-packages/gunicorn/workers/ggevent.py", line 203, in init_process
    super(GeventWorker, self).init_process()
  File "/Users/apple/anaconda3/lib/python3.7/site-packages/gunicorn/workers/base.py", line 129, in init_process
    self.load_wsgi()
  File "/Users/apple/anaconda3/lib/python3.7/site-packages/gunicorn/workers/base.py", line 138, in load_wsgi
    self.wsgi = self.app.wsgi()
  File "/Users/apple/anaconda3/lib/python3.7/site-packages/gunicorn/app/base.py", line 67, in wsgi
    self.callable = self.load()
  File "/Users/apple/anaconda3/lib/python3.7/site-packages/gunicorn/app/wsgiapp.py", line 52, in load
    return self.load_wsgiapp()
  File "/Users/apple/anaconda3/lib/python3.7/site-packages/gunicorn/app/wsgiapp.py", line 41, in load_wsgiapp
    return util.import_app(self.app_uri)
  File "/Users/apple/anaconda3/lib/python3.7/site-packages/gunicorn/util.py", line 350, in import_app
    __import__(module)
  File "/Users/apple/Desktop/query_mobile/app.py", line 5, in <module>
    from query import query_all
ImportError: cannot import name 'query_all' from 'query' (unknown location)
[2018-12-12 14:15:55 +0800] [30976] [INFO] Worker exiting (pid: 30976)
[2018-12-12 14:15:55 +0800] [30977] [ERROR] Exception in worker process
Traceback (most recent call last):
  File "/Users/apple/anaconda3/lib/python3.7/site-packages/gunicorn/arbiter.py", line 583, in spawn_worker
    worker.init_process()
  File "/Users/apple/anaconda3/lib/python3.7/site-packages/gunicorn/workers/ggevent.py", line 203, in init_process
    super(GeventWorker, self).init_process()
  File "/Users/apple/anaconda3/lib/python3.7/site-packages/gunicorn/workers/base.py", line 129, in init_process
    self.load_wsgi()
  File "/Users/apple/anaconda3/lib/python3.7/site-packages/gunicorn/workers/base.py", line 138, in load_wsgi
    self.wsgi = self.app.wsgi()
  File "/Users/apple/anaconda3/lib/python3.7/site-packages/gunicorn/app/base.py", line 67, in wsgi
    self.callable = self.load()
  File "/Users/apple/anaconda3/lib/python3.7/site-packages/gunicorn/app/wsgiapp.py", line 52, in load
    return self.load_wsgiapp()
  File "/Users/apple/anaconda3/lib/python3.7/site-packages/gunicorn/app/wsgiapp.py", line 41, in load_wsgiapp
    return util.import_app(self.app_uri)
  File "/Users/apple/anaconda3/lib/python3.7/site-packages/gunicorn/util.py", line 350, in import_app
    __import__(module)
  File "/Users/apple/Desktop/query_mobile/app.py", line 5, in <module>
    from query import query_all
ImportError: cannot import name 'query_all' from 'query' (unknown location)
[2018-12-12 14:15:55 +0800] [30977] [INFO] Worker exiting (pid: 30977)
[2018-12-12 14:15:55 +0800] [30965] [INFO] Shutting down: Master
[2018-12-12 14:15:55 +0800] [30965] [INFO] Reason: Worker failed to boot.
[2018-12-12 14:17:20 +0800] [31025] [INFO] Starting gunicorn 19.9.0
[2018-12-12 14:17:20 +0800] [31025] [INFO] Listening at: http://0.0.0.0:6789 (31025)
[2018-12-12 14:17:20 +0800] [31025] [INFO] Using worker: gevent
[2018-12-12 14:17:20 +0800] [31033] [INFO] Booting worker with pid: 31033
[2018-12-12 14:17:20 +0800] [31034] [INFO] Booting worker with pid: 31034
[2018-12-12 14:17:20 +0800] [31035] [INFO] Booting worker with pid: 31035
[2018-12-12 14:17:20 +0800] [31036] [INFO] Booting worker with pid: 31036
[2018-12-12 14:18:59 +0800] [31078] [INFO] Starting gunicorn 19.9.0
[2018-12-12 14:18:59 +0800] [31078] [INFO] Listening at: http://0.0.0.0:6789 (31078)
[2018-12-12 14:18:59 +0800] [31078] [INFO] Using worker: gevent
[2018-12-12 14:18:59 +0800] [31086] [INFO] Booting worker with pid: 31086
[2018-12-12 14:18:59 +0800] [31087] [INFO] Booting worker with pid: 31087
[2018-12-12 14:18:59 +0800] [31088] [INFO] Booting worker with pid: 31088
[2018-12-12 14:18:59 +0800] [31089] [INFO] Booting worker with pid: 31089
[2018-12-12 14:20:01 +0800] [31131] [INFO] Starting gunicorn 19.9.0
[2018-12-12 14:20:01 +0800] [31131] [INFO] Listening at: http://0.0.0.0:6789 (31131)
[2018-12-12 14:20:01 +0800] [31131] [INFO] Using worker: gevent
[2018-12-12 14:20:01 +0800] [31139] [INFO] Booting worker with pid: 31139
[2018-12-12 14:20:01 +0800] [31140] [INFO] Booting worker with pid: 31140
[2018-12-12 14:20:01 +0800] [31141] [INFO] Booting worker with pid: 31141
[2018-12-12 14:20:01 +0800] [31142] [INFO] Booting worker with pid: 31142
[2018-12-12 14:24:07 +0800] [31192] [INFO] Starting gunicorn 19.9.0
[2018-12-12 14:24:07 +0800] [31192] [ERROR] Connection in use: ('0.0.0.0', 6789)
[2018-12-12 14:24:07 +0800] [31192] [ERROR] Retrying in 1 second.
[2018-12-12 14:24:08 +0800] [31192] [ERROR] Connection in use: ('0.0.0.0', 6789)
[2018-12-12 14:24:08 +0800] [31192] [ERROR] Retrying in 1 second.
[2018-12-12 14:24:09 +0800] [31192] [ERROR] Connection in use: ('0.0.0.0', 6789)
[2018-12-12 14:24:09 +0800] [31192] [ERROR] Retrying in 1 second.
[2018-12-12 14:24:10 +0800] [31192] [ERROR] Connection in use: ('0.0.0.0', 6789)
[2018-12-12 14:24:10 +0800] [31192] [ERROR] Retrying in 1 second.
[2018-12-12 14:24:11 +0800] [31192] [ERROR] Connection in use: ('0.0.0.0', 6789)
[2018-12-12 14:24:11 +0800] [31192] [ERROR] Retrying in 1 second.
[2018-12-12 14:24:12 +0800] [31192] [ERROR] Can't connect to ('0.0.0.0', 6789)
[2018-12-12 14:24:40 +0800] [31233] [INFO] Starting gunicorn 19.9.0
[2018-12-12 14:24:40 +0800] [31233] [INFO] Listening at: http://0.0.0.0:6789 (31233)
[2018-12-12 14:24:40 +0800] [31233] [INFO] Using worker: gevent
[2018-12-12 14:24:40 +0800] [31241] [INFO] Booting worker with pid: 31241
[2018-12-12 14:24:41 +0800] [31242] [INFO] Booting worker with pid: 31242
[2018-12-12 14:24:41 +0800] [31243] [INFO] Booting worker with pid: 31243
[2018-12-12 14:24:41 +0800] [31244] [INFO] Booting worker with pid: 31244
[2018-12-12 14:26:59 +0800] [31306] [INFO] Starting gunicorn 19.9.0
[2018-12-12 14:26:59 +0800] [31306] [INFO] Listening at: http://0.0.0.0:6789 (31306)
[2018-12-12 14:26:59 +0800] [31306] [INFO] Using worker: gevent
[2018-12-12 14:26:59 +0800] [31314] [INFO] Booting worker with pid: 31314
[2018-12-12 14:26:59 +0800] [31315] [INFO] Booting worker with pid: 31315
[2018-12-12 14:26:59 +0800] [31316] [INFO] Booting worker with pid: 31316
[2018-12-12 14:26:59 +0800] [31317] [INFO] Booting worker with pid: 31317
[2018-12-12 14:55:15 +0800] [31642] [INFO] Starting gunicorn 19.9.0
[2018-12-12 14:55:15 +0800] [31642] [INFO] Listening at: http://0.0.0.0:6789 (31642)
[2018-12-12 14:55:15 +0800] [31642] [INFO] Using worker: gevent
[2018-12-12 14:55:15 +0800] [31650] [INFO] Booting worker with pid: 31650
[2018-12-12 14:55:15 +0800] [31651] [INFO] Booting worker with pid: 31651
[2018-12-12 14:55:15 +0800] [31652] [INFO] Booting worker with pid: 31652
[2018-12-12 14:55:15 +0800] [31653] [INFO] Booting worker with pid: 31653

Error: '127.0.0.1' is not a valid port number.

[2018-12-12 16:19:38 +0800] [33135] [INFO] Starting gunicorn 19.9.0
[2018-12-12 16:19:38 +0800] [33135] [INFO] Listening at: http://127.0.0.1:6789 (33135)
[2018-12-12 16:19:38 +0800] [33135] [INFO] Using worker: gevent
[2018-12-12 16:19:38 +0800] [33143] [INFO] Booting worker with pid: 33143
[2018-12-12 16:19:38 +0800] [33144] [INFO] Booting worker with pid: 33144
[2018-12-12 16:19:38 +0800] [33145] [INFO] Booting worker with pid: 33145
[2018-12-12 16:19:38 +0800] [33146] [INFO] Booting worker with pid: 33146
[2018-12-12 16:24:19 +0800] [33289] [INFO] Starting gunicorn 19.9.0
[2018-12-12 16:24:19 +0800] [33289] [INFO] Listening at: http://127.0.0.1:6789 (33289)
[2018-12-12 16:24:19 +0800] [33289] [INFO] Using worker: gevent
[2018-12-12 16:24:19 +0800] [33297] [INFO] Booting worker with pid: 33297
[2018-12-12 16:24:19 +0800] [33298] [INFO] Booting worker with pid: 33298
[2018-12-12 16:24:19 +0800] [33299] [INFO] Booting worker with pid: 33299
[2018-12-12 16:24:19 +0800] [33300] [INFO] Booting worker with pid: 33300
sougou_cookie.py:17: DeprecationWarning: use options instead of chrome_options
  driver = webdriver.Chrome(chrome_options=chrome_options)
Traceback (most recent call last):
  File "/Users/apple/anaconda3/lib/python3.7/site-packages/redis/connection.py", line 177, in _read_from_socket
    raise socket.error(SERVER_CLOSED_CONNECTION_ERROR)
OSError: Connection closed by server.

During handling of the above exception, another exception occurred:

Traceback (most recent call last):
  File "/Users/apple/anaconda3/lib/python3.7/site-packages/redis/client.py", line 668, in execute_command
    return self.parse_response(connection, command_name, **options)
  File "/Users/apple/anaconda3/lib/python3.7/site-packages/redis/client.py", line 680, in parse_response
    response = connection.read_response()
  File "/Users/apple/anaconda3/lib/python3.7/site-packages/redis/connection.py", line 624, in read_response
    response = self._parser.read_response()
  File "/Users/apple/anaconda3/lib/python3.7/site-packages/redis/connection.py", line 284, in read_response
    response = self._buffer.readline()
  File "/Users/apple/anaconda3/lib/python3.7/site-packages/redis/connection.py", line 216, in readline
    self._read_from_socket()
  File "/Users/apple/anaconda3/lib/python3.7/site-packages/redis/connection.py", line 191, in _read_from_socket
    (e.args,))
redis.exceptions.ConnectionError: Error while reading from socket: ('Connection closed by server.',)

During handling of the above exception, another exception occurred:

Traceback (most recent call last):
  File "/Users/apple/anaconda3/lib/python3.7/site-packages/redis/connection.py", line 484, in connect
    sock = self._connect()
  File "/Users/apple/anaconda3/lib/python3.7/site-packages/redis/connection.py", line 541, in _connect
    raise err
  File "/Users/apple/anaconda3/lib/python3.7/site-packages/redis/connection.py", line 529, in _connect
    sock.connect(socket_address)
ConnectionRefusedError: [Errno 61] Connection refused

During handling of the above exception, another exception occurred:

Traceback (most recent call last):
  File "sougou_cookie.py", line 42, in <module>
    get_cookies()
  File "sougou_cookie.py", line 25, in get_cookies
    num = cache.cookie_count()
  File "/Users/apple/Desktop/query_mobile/tools/redis_db.py", line 31, in cookie_count
    return self.r.scard(config.REDIS_SET_NAME)
  File "/Users/apple/anaconda3/lib/python3.7/site-packages/redis/client.py", line 1604, in scard
    return self.execute_command('SCARD', name)
  File "/Users/apple/anaconda3/lib/python3.7/site-packages/redis/client.py", line 673, in execute_command
    connection.send_command(*args)
  File "/Users/apple/anaconda3/lib/python3.7/site-packages/redis/connection.py", line 610, in send_command
    self.send_packed_command(self.pack_command(*args))
  File "/Users/apple/anaconda3/lib/python3.7/site-packages/redis/connection.py", line 585, in send_packed_command
    self.connect()
  File "/Users/apple/anaconda3/lib/python3.7/site-packages/redis/connection.py", line 489, in connect
    raise ConnectionError(self._error_message(e))
redis.exceptions.ConnectionError: Error 61 connecting to 127.0.0.1:6379. Connection refused.
